File: data/burn2_blue_9000s_x1_100p_01.txt
#Acq. time (s)=	9000
#Accumulations=	1
#Range (cm-¹)=	1000...3000
#Windows=	1
#Auto scanning=	Off
#Autofocus=	Off
#Macrospot=	Off
#AutoExposure=	Off
#Spike filter=	Off
#Delay time (s)=	0
#Binning=	1
#Readout mode=	Signal
#DeNoise=	Off
#ICS correction=	Off
#Dark correction=	Off
#Inst. Process=	Off
#Detector Gain=	Best Dynamic Range
#Detector ADC=	45 kHz
#Detector temperature (°C)=	-59.91
#Instrument=	LabRAM HR Evol
#Detector=	Syncerity OE
#Objective=	x100_VIS_LWD
#Grating=	300 (600nm)
#ND Filter=	100%
#Laser=	488nm_Edge
#Hole=	199.981
#Range=	Visible
#StageXY=	75x50mm Scan+
#StageZ=	Z motor
#X (µm)=	0
#Y (µm)=	0
#Z (µm)=	-4154.3
#Full time(hh:mm)=	2:30
#Project=
#Sample=
#Site=
#Title=	burn2_blue_9000s_x1_100p
#Remark=
#Date=	25.09.2024 14:16
#Acquired=	25.09.2024 14:16:32
#AxisType[0]=Intens
#AxisUnit[0]=Cnt
#AxisType[1]=Spectr
#AxisUnit[1]=1/cm
1001.24	64935
1005.31	64935
1009.37	64935
1013.43	64935
1017.49	36852
1021.54	26850
1025.6	24296
1029.65	21912
1033.7	15148
1037.75	10870
1041.8	9638
1045.85	9398
1049.89	9046
1053.93	8566
1057.97	7172
1062.01	4058
1066.05	756
1070.09	-600
1074.12	-600
1078.15	-600
1082.18	-600
1086.21	-600
1090.24	-600
1094.27	-600
1098.29	-600
1102.31	-600
1106.33	-600
1110.35	-600
1114.37	-600
1118.39	-600
1122.4	-600
1126.41	-600
1130.42	-600
1134.43	-600
1138.44	-600
1142.45	-600
1146.45	-600
1150.45	-600
1154.45	-600
1158.45	-600
1162.45	-600
1166.44	-600
1170.44	-600
1174.43	-600
1178.42	-600
1182.41	-600
1186.4	-600
1190.38	-600
1194.37	-600
1198.35	-600
1202.33	-600
1206.31	-600
1210.28	-600
1214.26	-600
1218.24	-600
1222.21	-600
1226.18	-600
1230.15	-600
1234.12	-600
1238.08	-600
1242.04	-600
1246.01	-600
1249.97	-600
1253.93	-600
1257.89	-600
1261.84	-600
1265.79	-600
1269.75	-600
1273.7	-600
1277.65	-600
1281.59	-600
1285.54	-600
1289.48	-600
1293.43	-600
1297.37	-600
1301.31	-600
1305.25	-600
1309.18	-600
1313.12	-600
1317.05	-600
1320.98	-600
1324.91	-600
1328.84	-600
1332.76	-600
1336.69	-600
1340.61	-600
1344.53	-600
1348.45	-600
1352.37	-600
1356.29	-600
1360.2	-600
1364.12	-600
1368.03	-600
1371.94	-600
1375.85	-600
1379.75	-600
1383.66	-600
1387.56	-600
1391.47	-600
1395.37	-600
1399.27	-600
1403.16	-600
1407.06	-600
1410.95	-600
1414.84	-600
1418.73	-600
1422.63	-600
1426.51	-600
1430.4	-600
1434.28	-600
1438.17	-600
1442.05	-600
1445.93	-600
1449.8	-600
1453.68	-600
1457.56	-600
1461.43	-600
1465.3	-600
1469.17	-600
1473.04	-600
1476.91	-600
1480.77	-600
1484.63	-600
1488.5	-600
1492.36	-600
1496.22	-600
1500.07	-600
1503.93	-600
1507.78	-600
1511.64	-600
1515.49	-600
1519.34	-600
1523.18	-600
1527.03	-600
1530.87	-600
1534.72	-600
1538.56	-600
1542.4	-600
1546.24	-600
1550.07	-600
1553.91	-600
1557.74	-600
1561.57	-600
1565.41	-600
1569.23	-600
1573.06	-600
1576.89	-600
1580.71	-600
1584.54	-600
1588.36	-600
1592.18	-600
1595.99	-600
1599.81	-600
1603.63	-600
1607.44	-600
1611.25	-600
1615.06	-600
1618.87	-600
1622.68	-600
1626.48	-600
1630.29	-600
1634.09	-600
1637.89	-600
1641.69	-600
1645.49	-600
1649.28	-600
1653.08	-600
1656.87	-600
1660.66	-600
1664.45	-600
1668.24	-600
1672.03	-600
1675.81	-600
1679.6	-600
1683.38	-600
1687.16	-600
1690.94	-600
1694.72	-600
1698.49	-600
1702.27	-600
1706.04	-600
1709.81	-600
1713.58	-600
1717.35	-600
1721.12	-600
1724.88	-600
1728.65	-600
1732.41	-600
1736.17	-600
1739.93	-600
1743.69	-600
1747.45	-600
1751.2	-600
1754.95	-600
1758.7	-600
1762.46	-600
1766.2	-600
1769.95	-600
1773.7	-600
1777.44	-600
1781.18	-600
1784.93	-600
1788.66	-600
1792.4	-600
1796.14	-600
1799.88	-600
1803.61	-600
1807.34	-600
1811.07	-600
1814.8	-600
1818.53	-600
1822.25	-600
1825.98	-600
1829.7	-600
1833.42	-600
1837.14	-600
1840.86	-600
1844.58	-600
1848.29	-600
1852.01	-600
1855.72	-600
1859.43	-600
1863.14	-600
1866.85	-600
1870.55	-600
1874.26	-600
1877.96	-600
1881.67	-600
1885.37	-600
1889.06	-600
1892.76	-600
1896.46	-600
1900.15	-600
1903.85	-600
1907.54	-600
1911.23	-600
1914.92	-600
1918.6	-600
1922.29	-600
1925.97	-600
1929.66	-600
1933.34	-600
1937.02	-600
1940.7	-600
1944.37	-600
1948.05	-600
1951.72	-600
1955.39	-600
1959.06	-600
1962.73	-600
1966.4	-600
1970.07	-600
1973.73	-600
1977.4	-600
1981.06	-600
1984.72	-600
1988.38	-600
1992.04	-600
1995.69	-600
1999.35	-600
2003	-600
2006.65	-600
2010.3	-600
2013.95	-600
2017.6	-600
2021.25	-600
2024.89	-600
2028.53	-600
2032.18	-600
2035.82	-600
2039.46	-600
2043.09	-600
2046.73	-600
2050.36	-600
2054	-600
2057.63	-600
2061.26	-600
2064.89	-600
2068.51	-600
2072.14	-600
2075.76	-600
2079.39	-600
2083.01	-600
2086.63	-600
2090.25	-600
2093.86	-600
2097.48	-600
2101.09	-600
2104.7	-600
2108.32	-600
2111.93	-600
2115.53	-600
2119.14	-600
2122.75	-600
2126.35	-600
2129.95	-600
2133.55	-600
2137.16	-600
2140.75	-600
2144.35	-600
2147.95	-600
2151.54	-600
2155.13	-600
2158.72	-600
2162.31	-600
2165.9	-600
2169.49	-600
2173.07	-600
2176.66	-600
2180.24	-600
2183.82	-600
2187.4	-600
2190.98	-600
2194.56	-600
2198.13	-600
2201.71	-600
2205.28	-600
2208.85	-600
2212.42	-600
2215.99	-600
2219.56	-600
2223.12	-600
2226.69	-600
2230.25	-600
2233.81	-600
2237.37	-600
2240.93	-600
2244.49	-600
2248.04	-600
2251.6	-600
2255.15	-600
2258.7	-600
2262.25	-600
2265.8	-600
2269.35	-600
2272.9	-600
2276.44	-600
2279.98	-600
2283.52	-600
2287.07	-600
2290.61	-600
2294.14	-600
2297.68	-600
2301.21	-600
2304.75	-600
2308.28	-600
2311.81	-600
2315.34	-600
2318.87	-600
2322.39	-600
2325.92	-600
2329.44	-600
2332.97	-600
2336.49	-600
2340.01	-600
2343.52	-600
2347.04	-600
2350.56	-600
2354.07	-600
2357.58	-600
2361.09	-600
2364.6	-600
2368.11	-600
2371.62	-600
2375.13	-600
2378.63	-600
2382.13	-600
2385.64	-600
2389.14	-600
2392.63	-600
2396.13	-600
2399.63	-600
2403.12	-600
2406.62	-600
2410.11	-600
2413.6	-600
2417.09	-600
2420.58	-600
2424.06	-600
2427.55	-600
2431.03	-600
2434.51	-600
2438	-600
2441.48	-600
2444.96	-600
2448.43	-600
2451.91	-600
2455.38	-600
2458.85	-600
2462.33	-600
2465.8	-600
2469.27	-600
2472.73	-600
2476.2	-600
2479.66	-600
2483.13	-600
2486.59	-600
2490.05	-600
2493.51	-600
2496.97	-600
2500.43	-600
2503.88	-600
2507.34	-600
2510.79	-600
2514.24	-600
2517.69	-600
2521.14	-600
2524.59	-600
2528.03	-600
2531.48	-600
2534.92	-600
2538.36	-600
2541.8	-600
2545.24	-600
2548.68	-600
2552.12	-600
2555.55	-600
2558.99	-600
2562.42	-600
2565.85	-600
2569.28	-600
2572.71	-600
2576.14	-600
2579.56	-600
2582.99	-600
2586.41	-600
2589.83	-600
2593.25	-600
2596.67	-600
2600.09	-600
2603.51	-600
2606.92	-600
2610.34	-600
2613.75	-600
2617.16	-600
2620.57	-600
2623.98	-600
2627.39	-600
2630.79	-600
2634.2	-600
2637.6	-600
2641	-600
2644.4	-600
2647.8	-600
2651.2	-600
2654.6	-600
2657.99	-600
2661.39	-600
2664.78	-600
2668.17	-600
2671.56	-600
2674.95	-600
2678.34	-600
2681.73	-600
2685.11	-600
2688.5	-600
2691.88	-600
2695.26	-600
2698.64	-600
2702.02	-600
2705.4	-600
2708.77	-600
2712.15	-600
2715.52	-600
2718.89	-600
2722.26	-600
2725.63	-600
2729	-600
2732.37	-600
2735.73	-600
2739.1	-600
2742.46	-600
2745.82	-600
2749.18	-600
2752.54	-600
2755.9	-600
2759.26	-600
2762.61	-600
2765.97	-600
2769.32	-600
2772.67	-600
2776.02	-600
2779.37	-600
2782.72	-600
2786.06	-600
2789.41	-600
2792.75	-600
2796.1	-600
2799.44	-600
2802.78	-600
2806.11	-600
2809.45	-600
2812.79	-600
2816.12	-600
2819.46	-600
2822.79	-600
2826.12	-600
2829.45	-600
2832.78	-600
2836.1	-600
2839.43	-600
2842.75	-600
2846.08	-600
2849.4	-600
2852.72	-600
2856.04	-600
2859.36	-600
2862.68	-600
2865.99	-600
2869.31	-600
2872.62	-600
2875.93	-600
2879.24	-600
2882.55	-600
2885.86	-600
2889.17	-600
2892.47	-600
2895.78	-600
2899.08	-600
2902.38	-600
2905.68	-600
2908.98	-600
2912.28	-600
2915.58	-600
2918.87	-600
2922.17	-600
2925.46	-600
2928.75	-600
2932.04	-600
2935.33	-600
2938.62	-600
2941.91	-600
2945.19	-600
2948.47	-600
2951.76	-600
2955.04	-600
2958.32	-600
2961.6	-600
2964.88	-600
2968.15	-600
2971.43	-600
2974.7	-600
2977.98	-600
2981.25	-600
2984.52	-600
2987.79	-600
2991.06	-600
2994.32	-600
2997.59	-600