File: data/burn_blue_10s_x180_100p_01.txt
#Acq. time (s)=	10
#Accumulations=	180
#Range (cm-¹)=	1000...3000
#Windows=	1
#Auto scanning=	Off
#Autofocus=	Off
#Macrospot=	Off
#AutoExposure=	Off
#Spike filter=	Multiple accum.
#Delay time (s)=	0
#Binning=	1
#Readout mode=	Signal
#DeNoise=	Off
#ICS correction=	Off
#Dark correction=	Off
#Inst. Process=	Off
#Detector Gain=	Best Dynamic Range
#Detector ADC=	45 kHz
#Detector temperature (°C)=	-60.1
#Instrument=	LabRAM HR Evol
#Detector=	Syncerity OE
#Objective=	x100_VIS_LWD
#Grating=	300 (600nm)
#ND Filter=	100%
#Laser=	488nm_Edge
#Hole=	199.981
#Range=	Visible
#StageXY=	75x50mm Scan+
#StageZ=	Z motor
#X (µm)=	0
#Y (µm)=	0
#Z (µm)=	-4113.3
#Full time(mm:ss)=	30:36
#Project=
#Sample=
#Site=
#Title=	burn_blue_10s_x180_100p
#Remark=
#Date=	25.09.2024 10:24
#Acquired=	25.09.2024 10:24:12
#AxisType[0]=Intens
#AxisUnit[0]=Cnt
#AxisType[1]=Spectr
#AxisUnit[1]=1/cm
1001.24	1678.74
1005.31	1682.84
1009.37	1694.44
1013.43	1704.7
1017.49	1714.23
1021.54	1726.18
1025.6	1743.29
1029.65	1761.79
1033.7	1788.53
1037.75	1800.65
1041.8	1816.88
1045.85	1834.79
1049.89	1848.89
1053.93	1861.54
1057.97	1874.3
1062.01	1880.99
1066.05	1896.31
1070.09	1913.91
1074.12	1948.66
1078.15	2008.77
1082.18	2080.69
1086.21	2108.72
1090.24	2054.34
1094.27	1966.67
1098.29	1900.96
1102.31	1858.01
1106.33	1839.35
1110.35	1829.68
1114.37	1827.43
1118.39	1821.74
1122.4	1812.41
1126.41	1812.69
1130.42	1806.88
1134.43	1815.5
1138.44	1820.64
1142.45	1816.53
1146.45	1824.42
1150.45	1834.77
1154.45	1837.25
1158.45	1840.64
1162.45	1853.05
1166.44	1853.92
1170.44	1862.23
1174.43	1866.94
1178.42	1868.69
1182.41	1862.12
1186.4	1871.79
1190.38	1870.63
1194.37	1875.59
1198.35	1886.5
1202.33	1881.65
1206.31	1886.88
1210.28	1883.39
1214.26	1893.64
1218.24	1910.59
1222.21	1920.81
1226.18	1916.47
1230.15	1897.47
1234.12	1877.11
1238.08	1852.87
1242.04	1829.99
1246.01	1817.46
1249.97	1808.3
1253.93	1805.88
1257.89	1815.06
1261.84	1819.73
1265.79	1834.65
1269.75	1842.17
1273.7	1851.21
1277.65	1870.92
1281.59	1888.44
1285.54	1909.84
1289.48	1923.98
1293.43	1948.15
1297.37	1967.29
1301.31	1994.89
1305.25	2016.32
1309.18	2045.12
1313.12	2069.91
1317.05	2102.16
1320.98	2119.42
1324.91	2138.44
1328.84	2158.12
1332.76	2166.79
1336.69	2167.73
1340.61	2179.15
1344.53	2174.88
1348.45	2176.1
1352.37	2168.45
1356.29	2162.22
1360.2	2152.48
1364.12	2148.18
1368.03	2142.55
1371.94	2144.95
1375.85	2146.97
1379.75	2135.58
1383.66	2107.54
1387.56	2099.51
1391.47	2084.49
1395.37	2081.21
1399.27	2083.12
1403.16	2080.76
1407.06	2082.68
1410.95	2082.86
1414.84	2081.37
1418.73	2085.9
1422.63	2095.21
1426.51	2097.84
1430.4	2109.06
1434.28	2126.17
1438.17	2145.68
1442.05	2158.97
1445.93	2192.48
1449.8	2222.89
1453.68	2247.24
1457.56	2274.55
1461.43	2298.32
1465.3	2328.2
1469.17	2311.85
1473.04	2307.48
1476.91	2333.32
1480.77	2391.33
1484.63	2455.51
1488.5	2507.78
1492.36	2540.02
1496.22	2521.75
1500.07	2501.75
1503.93	2501.67
1507.78	2524.25
1511.64	2553.77
1515.49	2599.55
1519.34	2658.94
1523.18	2731.73
1527.03	2830.64
1530.87	2950.51
1534.72	3098.48
1538.56	3286.77
1542.4	3545.5
1546.24	3882.01
1550.07	4336.54
1553.91	4984.96
1557.74	5959.98
1561.57	7525.44
1565.41	10248.1
1569.23	15256.9
1573.06	24804.1
1576.89	40137.8
1580.71	51228.6
1584.54	43182.4
1588.36	27204.6
1592.18	16220.6
1595.99	10621.4
1599.81	7716.97
1603.63	6045.95
1607.44	5008.46
1611.25	4334.82
1615.06	3853.22
1618.87	3516.1
1622.68	3252.01
1626.48	3023.4
1630.29	2853.26
1634.09	2731.48
1637.89	2644.47
1641.69	2571.43
1645.49	2512.29
1649.28	2461.98
1653.08	2424.03
1656.87	2387.43
1660.66	2357.31
1664.45	2335.03
1668.24	2320.67
1672.03	2303.86
1675.81	2296.18
1679.6	2282.84
1683.38	2277.51
1687.16	2263.59
1690.94	2252.67
1694.72	2247.56
1698.49	2241.7
1702.27	2234.37
1706.04	2238.69
1709.81	2247.5
1713.58	2241.15
1717.35	2248.19
1721.12	2256.87
1724.88	2267.78
1728.65	2271.67
1732.41	2292.78
1736.17	2312.97
1739.93	2335.73
1743.69	2368.19
1747.45	2401.78
1751.2	2439.64
1754.95	2456.33
1758.7	2437.56
1762.46	2371.28
1766.2	2333.32
1769.95	2319.61
1773.7	2312
1777.44	2292.92
1781.18	2278.84
1784.93	2265.49
1788.66	2255.35
1792.4	2245.66
1796.14	2235.94
1799.88	2233.52
1803.61	2226.67
1807.34	2217.56
1811.07	2217.49
1814.8	2209.34
1818.53	2200.37
1822.25	2182.79
1825.98	2175.8
1829.7	2165.59
1833.42	2160.51
1837.14	2157.29
1840.86	2148.72
1844.58	2151.81
1848.29	2150.25
1852.01	2148.91
1855.72	2154.16
1859.43	2154.09
1863.14	2155.7
1866.85	2169.57
1870.55	2168.01
1874.26	2176
1877.96	2176.5
1881.67	2181.3
1885.37	2186.22
1889.06	2188.28
1892.76	2193.05
1896.46	2194.27
1900.15	2191.44
1903.85	2195.87
1907.54	2198.01
1911.23	2200.82
1914.92	2202.21
1918.6	2204.74
1922.29	2209.65
1925.97	2215.6
1929.66	2222.13
1933.34	2222.11
1937.02	2229.23
1940.7	2235.48
1944.37	2241.86
1948.05	2247.52
1951.72	2248.89
1955.39	2255.82
1959.06	2260.21
1962.73	2262.63
1966.4	2275.27
1970.07	2279.63
1973.73	2281.15
1977.4	2284.1
1981.06	2286.98
1984.72	2292.56
1988.38	2295.63
1992.04	2300.74
1995.69	2308.41
1999.35	2306.76
2003	2309.6
2006.65	2314.19
2010.3	2317.02
2013.95	2321.77
2017.6	2325.91
2021.25	2329.92
2024.89	2336.1
2028.53	2332.04
2032.18	2335.53
2035.82	2341.61
2039.46	2344.31
2043.09	2349.43
2046.73	2341.34
2050.36	2348.37
2054	2355.21
2057.63	2351.04
2061.26	2350.07
2064.89	2343.72
2068.51	2331.42
2072.14	2325.83
2075.76	2312.67
2079.39	2300
2083.01	2295.98
2086.63	2287.4
2090.25	2284.19
2093.86	2286
2097.48	2280.87
2101.09	2284.1
2104.7	2285.99
2108.32	2284.95
2111.93	2290.25
2115.53	2294.09
2119.14	2292.64
2122.75	2294.58
2126.35	2297.83
2129.95	2295.02
2133.55	2299.31
2137.16	2305.26
2140.75	2309.77
2144.35	2308.18
2147.95	2310.31
2151.54	2313.35
2155.13	2314.88
2158.72	2322.32
2162.31	2323.97
2165.9	2328.9
2169.49	2334.75
2173.07	2340.4
2176.66	2341.55
2180.24	2352.11
2183.82	2356.51
2187.4	2357.39
2190.98	2357.01
2194.56	2349.65
2198.13	2341.93
2201.71	2331.12
2205.28	2321.51
2208.85	2315.61
2212.42	2308.08
2215.99	2305.51
2219.56	2308.67
2223.12	2301.42
2226.69	2303.35
2230.25	2301.25
2233.81	2302.28
2237.37	2295.94
2240.93	2297.13
2244.49	2295.07
2248.04	2294.33
2251.6	2296.01
2255.15	2294.07
2258.7	2299.37
2262.25	2299.48
2265.8	2296.18
2269.35	2300.84
2272.9	2304.79
2276.44	2297.61
2279.98	2300.51
2283.52	2303.54
2287.07	2313.98
2290.61	2306.84
2294.14	2308.84
2297.68	2315.19
2301.21	2314.96
2304.75	2311.13
2308.28	2319.26
2311.81	2325.18
2315.34	2329.18
2318.87	2362.15
2322.39	2394.32
2325.92	2435.86
2329.44	2461.27
2332.97	2410.1
2336.49	2367.42
2340.01	2350.84
2343.52	2343.26
2347.04	2347.52
2350.56	2348.37
2354.07	2350.97
2357.58	2353.81
2361.09	2355.64
2364.6	2355.16
2368.11	2359.41
2371.62	2359.75
2375.13	2371.36
2378.63	2360.93
2382.13	2367.03
2385.64	2368.59
2389.14	2373.15
2392.63	2378.74
2396.13	2389.35
2399.63	2400.47
2403.12	2415.84
2406.62	2438.18
2410.11	2471.34
2413.6	2533.66
2417.09	2635.34
2420.58	2798.22
2424.06	3050.09
2427.55	3311.3
2431.03	3456.49
2434.51	3459.21
2438	3386.06
2441.48	3309.78
2444.96	3233.18
2448.43	3175.54
2451.91	3128.01
2455.38	3093.19
2458.85	3059.8
2462.33	3005.07
2465.8	2930.08
2469.27	2876.32
2472.73	2823.3
2476.2	2793.13
2479.66	2770.96
2483.13	2716.36
2486.59	2663.18
2490.05	2642.85
2493.51	2620.51
2496.97	2612.36
2500.43	2604.47
2503.88	2594.89
2507.34	2593.56
2510.79	2587.69
2514.24	2589.82
2517.69	2579.97
2521.14	2577.69
2524.59	2581.9
2528.03	2577.94
2531.48	2587.06
2534.92	2587.81
2538.36	2595.05
2541.8	2603.72
2545.24	2610.78
2548.68	2613.45
2552.12	2617.33
2555.55	2625.74
2558.99	2638.99
2562.42	2645.32
2565.85	2650.69
2569.28	2669.36
2572.71	2682.99
2576.14	2692.2
2579.56	2705.44
2582.99	2727.85
2586.41	2743.49
2589.83	2764.3
2593.25	2786.45
2596.67	2810.11
2600.09	2835.41
2603.51	2869.4
2606.92	2905.33
2610.34	2945.33
2613.75	2987.83
2617.16	3038.11
2620.57	3092.12
2623.98	3147.46
2627.39	3209.77
2630.79	3264.08
2634.2	3334.07
2637.6	3419.17
2641	3499.15
2644.4	3611.45
2647.8	3727.35
2651.2	3876.32
2654.6	4043.28
2657.99	4245.29
2661.39	4481.47
2664.78	4771.74
2668.17	5126.47
2671.56	5558.82
2674.95	6056.47
2678.34	6619.15
2681.73	7230.34
2685.11	7838.12
2688.5	8401.14
2691.88	8867.66
2695.26	9199.72
2698.64	9430.6
2702.02	9638.63
2705.4	9818.35
2708.77	10046.3
2712.15	10328.2
2715.52	10766.2
2718.89	11422
2722.26	12505.2
2725.63	14087.7
2729	16100.7
2732.37	17990.6
2735.73	18919.9
2739.1	18410.6
2742.46	16864.8
2745.82	14976.3
2749.18	13238.9
2752.54	11728.3
2755.9	10433.9
2759.26	9241.97
2762.61	8011.93
2765.97	6886.87
2769.32	5980.61
2772.67	5325.06
2776.02	4874.19
2779.37	4541.84
2782.72	4301.25
2786.06	4131.43
2789.41	3989.49
2792.75	3880.77
2796.1	3787.46
2799.44	3714.08
2802.78	3652.59
2806.11	3594.13
2809.45	3535.51
2812.79	3482.64
2816.12	3426.11
2819.46	3377.02
2822.79	3332.54
2826.12	3295.33
2829.45	3259.72
2832.78	3236.74
2836.1	3209.46
2839.43	3186.64
2842.75	3176.57
2846.08	3163.51
2849.4	3146.17
2852.72	3129.87
2856.04	3109.92
2859.36	3107.03
2862.68	3100.94
2865.99	3092.48
2869.31	3090.31
2872.62	3101.11
2875.93	3109.79
2879.24	3115.99
2882.55	3121.89
2885.86	3107.83
2889.17	3090.75
2892.47	3090.13
2895.78	3089.2
2899.08	3100.51
2902.38	3107.3
2905.68	3109.77
2908.98	3116.54
2912.28	3112.95
2915.58	3121.41
2918.87	3128.69
2922.17	3151.39
2925.46	3195.01
2928.75	3250.67
2932.04	3338.88
2935.33	3426.04
2938.62	3522.92
2941.91	3548.14
2945.19	3509.75
2948.47	3443.79
2951.76	3355.9
2955.04	3295.98
2958.32	3257.42
2961.6	3263.42
2964.88	3278.82
2968.15	3299.34
2971.43	3317.93
2974.7	3329.16
2977.98	3320.09
2981.25	3309.56
2984.52	3296.92
2987.79	3284.15
2991.06	3299.42
2994.32	3324.71
2997.59	3355.67