File: data/test2_15s_x10_25p_01.txt
#Acq. time (s)=	15
#Accumulations=	10
#Range (cm-¹)=	1000...3000
#Windows=	1
#Auto scanning=	Off
#Autofocus=	Off
#Macrospot=	Off
#AutoExposure=	Off
#Spike filter=	Multiple accum.
#Delay time (s)=	0
#Binning=	1
#Readout mode=	Signal
#DeNoise=	Off
#ICS correction=	Off
#Dark correction=	Off
#Inst. Process=	Off
#Detector Gain=	Best Dynamic Range
#Detector ADC=	45 kHz
#Detector temperature (°C)=	-60.1
#Instrument=	LabRAM HR Evol
#Detector=	Syncerity OE
#Objective=	x100_VIS_LWD
#Grating=	300 (600nm)
#ND Filter=	25%
#Laser=	633nm_Edge
#Hole=	199.981
#Range=	Visible
#StageXY=	75x50mm Scan+
#StageZ=	Z motor
#X (µm)=	0
#Y (µm)=	0
#Z (µm)=	-3272.5
#Full time(mm:ss)=	2:38
#Project=
#Sample=
#Site=
#Title=	test2_15s_x10_25p
#Remark=
#Date=	23.09.2024 11:10
#Acquired=	23.09.2024 11:10:37
#AxisType[0]=Intens
#AxisUnit[0]=Cnt
#AxisType[1]=Spectr
#AxisUnit[1]=1/cm
1000.94	422.222
1003.27	423.778
1005.6	418
1007.93	426.444
1010.26	418.667
1012.59	420
1014.91	421.333
1017.24	427.333
1019.57	424.889
1021.89	424
1024.22	422
1026.54	428.444
1028.86	433.333
1031.18	423.778
1033.5	429.111
1035.82	428.222
1038.15	434.222
1040.46	434.444
1042.78	431.778
1045.1	437.778
1047.42	446.222
1049.73	444.667
1052.05	445.111
1054.36	437.333
1056.68	438.444
1058.99	441.778
1061.3	445.111
1063.61	439.778
1065.92	443.778
1068.23	437.333
1070.54	448.889
1072.85	440.222
1075.16	445.556
1077.47	453.778
1079.77	453.111
1082.08	451.111
1084.38	448.889
1086.69	454
1088.99	448.667
1091.29	448.667
1093.6	448
1095.9	448.889
1098.2	454.444
1100.5	464.222
1102.8	451.556
1105.1	450.444
1107.39	461.111
1109.69	466.889
1111.99	446.667
1114.28	460.444
1116.58	468.222
1118.87	463.778
1121.16	460
1123.46	467.111
1125.75	468
1128.04	466
1130.33	469.111
1132.62	479.333
1134.91	472.889
1137.2	463.333
1139.48	471.778
1141.77	469.556
1144.06	469.556
1146.34	483.556
1148.63	478.222
1150.91	482.889
1153.19	480
1155.48	481.778
1157.76	465.111
1160.04	469.778
1162.32	479.111
1164.6	470.222
1166.88	481.333
1169.15	468.444
1171.43	472.889
1173.71	478
1175.98	479.333
1178.26	481.333
1180.53	476.889
1182.81	479.111
1185.08	476.667
1187.35	478.444
1189.62	478.889
1191.9	474.889
1194.17	487.778
1196.44	478.667
1198.7	481.778
1200.97	480.667
1203.24	477.333
1205.51	483.111
1207.77	477.333
1210.04	486.444
1212.3	484.222
1214.56	484.222
1216.83	485.333
1219.09	481.556
1221.35	484
1223.61	476.222
1225.87	479.778
1228.13	484.444
1230.39	464
1232.65	485.333
1234.91	486.889
1237.16	489.111
1239.42	487.556
1241.67	480.889
1243.93	484.444
1246.18	491.778
1248.43	484.667
1250.69	478.667
1252.94	486
1255.19	478.667
1257.44	471.333
1259.69	473.556
1261.94	483.111
1264.19	490
1266.43	485.778
1268.68	470.889
1270.93	473.778
1273.17	479.333
1275.41	473.111
1277.66	470.444
1279.9	489.333
1282.14	480
1284.39	482.222
1286.63	487.556
1288.87	480
1291.11	472.667
1293.35	482.222
1295.58	488
1297.82	483.778
1300.06	476.444
1302.29	478.667
1304.53	481.778
1306.76	490.889
1309	492.889
1311.23	483.778
1313.46	491.778
1315.7	480.444
1317.93	482
1320.16	489.556
1322.39	483.111
1324.61	489.778
1326.84	486.444
1329.07	489.556
1331.3	490
1333.52	477.111
1335.75	482.222
1337.98	487.556
1340.2	498.222
1342.42	494.667
1344.65	493.556
1346.87	490.889
1349.09	484.222
1351.31	489.556
1353.53	485.556
1355.75	506.222
1357.97	489.778
1360.18	490.444
1362.4	496.667
1364.62	486.667
1366.83	485.111
1369.05	491.333
1371.26	493.111
1373.48	497.333
1375.69	492.667
1377.9	488.222
1380.11	488.889
1382.33	489.111
1384.54	488.889
1386.75	499.111
1388.95	495.556
1391.16	494
1393.37	499.556
1395.58	486.667
1397.78	493.778
1399.99	504.444
1402.19	491.333
1404.4	501.556
1406.6	486.889
1408.8	495.778
1411.01	493.556
1413.21	488
1415.41	500.667
1417.61	492
1419.81	494
1422	500.444
1424.2	502.889
1426.4	505.111
1428.6	504.222
1430.79	507.111
1432.99	502
1435.18	504
1437.38	510.444
1439.57	504.222
1441.76	503.333
1443.95	502.222
1446.14	501.333
1448.33	503.556
1450.52	510.667
1452.71	504.667
1454.9	503.556
1457.09	507.111
1459.28	508.667
1461.46	499.778
1463.65	514.667
1465.83	506
1468.02	506.889
1470.2	504.444
1472.38	505.333
1474.57	510.444
1476.75	514
1478.93	511.111
1481.11	525.111
1483.29	527.333
1485.47	516.889
1487.65	510
1489.82	516.667
1492	520.889
1494.18	527.778
1496.35	513.778
1498.53	520.222
1500.7	526.444
1502.87	536.222
1505.05	521.333
1507.22	533.333
1509.39	524.889
1511.56	532.444
1513.73	529.778
1515.9	542.667
1518.07	522.222
1520.24	536.222
1522.4	545.778
1524.57	539.778
1526.74	536.222
1528.9	535.333
1531.07	542.222
1533.23	544.889
1535.39	545.556
1537.56	547.556
1539.72	560.222
1541.88	565.778
1544.04	571.778
1546.2	582
1548.36	584.667
1550.52	594
1552.68	608.222
1554.83	626.444
1556.99	632.889
1559.15	672
1561.3	706.444
1563.46	768.889
1565.61	836.444
1567.76	950
1569.92	1084.67
1572.07	1275.78
1574.22	1458
1576.37	1620.89
1578.52	1622.44
1580.67	1451.56
1582.82	1248.44
1584.97	1040
1587.11	903.778
1589.26	804.667
1591.41	733.556
1593.55	694.445
1595.7	656.667
1597.84	619.111
1599.99	603.111
1602.13	592
1604.27	587.556
1606.41	587.778
1608.55	569.111
1610.69	567.778
1612.83	558.889
1614.97	557.333
1617.11	557.111
1619.25	554.444
1621.38	539.111
1623.52	543.333
1625.66	544
1627.79	540.667
1629.92	531.111
1632.06	539.111
1634.19	545.556
1636.32	532.444
1638.45	536.444
1640.59	526.444
1642.72	529.111
1644.85	529.556
1646.97	532.889
1649.1	543.111
1651.23	532.667
1653.36	536.444
1655.48	534.667
1657.61	534
1659.73	540.444
1661.86	544.667
1663.98	536.444
1666.11	533.333
1668.23	538.222
1670.35	535.111
1672.47	532.667
1674.59	530
1676.71	528
1678.83	532.667
1680.95	531.778
1683.07	532.667
1685.19	535.556
1687.3	534.889
1689.42	536
1691.53	525.111
1693.65	534.889
1695.76	523.556
1697.87	520
1699.99	533.111
1702.1	535.333
1704.21	526.667
1706.32	537.556
1708.43	524.889
1710.54	526.667
1712.65	530.889
1714.76	526.222
1716.87	527.778
1718.97	523.111
1721.08	539.556
1723.19	533.555
1725.29	530.222
1727.39	520
1729.5	520.222
1731.6	533.556
1733.7	538.222
1735.8	536.222
1737.91	541.778
1740.01	547.111
1742.11	543.556
1744.21	546.667
1746.3	534.444
1748.4	539.333
1750.5	534.444
1752.6	531.778
1754.69	546.667
1756.79	535.333
1758.88	519.333
1760.98	524
1763.07	536.222
1765.16	537.111
1767.26	551.556
1769.35	538
1771.44	539.333
1773.53	546.444
1775.62	549.333
1777.71	548.222
1779.8	543.333
1781.88	548.444
1783.97	551.333
1786.06	545.333
1788.14	548.444
1790.23	538.667
1792.31	553.778
1794.4	543.333
1796.48	547.111
1798.56	546
1800.64	544.889
1802.73	553.333
1804.81	548.667
1806.89	533.556
1808.97	548
1811.05	543.333
1813.12	553.556
1815.2	556.444
1817.28	551.556
1819.35	541.778
1821.43	546
1823.51	552.667
1825.58	543.111
1827.65	539.556
1829.73	533.333
1831.8	543.333
1833.87	545.778
1835.94	543.333
1838.01	536.667
1840.08	552
1842.15	542.222
1844.22	544.222
1846.29	545.333
1848.36	546.222
1850.42	549.111
1852.49	537.778
1854.56	545.111
1856.62	554.889
1858.68	545.111
1860.75	545.333
1862.81	538.222
1864.88	532.445
1866.94	529.333
1869	530.667
1871.06	548
1873.12	535.555
1875.18	549.556
1877.24	544.444
1879.3	549.556
1881.35	548.222
1883.41	529.111
1885.47	553.111
1887.52	552.222
1889.58	546.889
1891.63	558.222
1893.69	541.111
1895.74	537.556
1897.79	555.556
1899.84	540.222
1901.89	555.333
1903.95	561.778
1906	555.333
1908.05	558
1910.09	546
1912.14	549.111
1914.19	555.111
1916.24	558.667
1918.28	561.778
1920.33	550
1922.37	552.445
1924.42	566.444
1926.46	550
1928.51	562.222
1930.55	558.222
1932.59	563.111
1934.63	563.778
1936.67	566
1938.71	554.444
1940.75	563.333
1942.79	558
1944.83	558.444
1946.87	556.667
1948.91	561.556
1950.94	560.444
1952.98	551.333
1955.01	557.556
1957.05	551.111
1959.08	552
1961.12	549.111
1963.15	551.111
1965.18	545.333
1967.21	552
1969.25	545.333
1971.27	553.111
1973.31	547.111
1975.33	542
1977.36	548.444
1979.39	552
1981.42	558.222
1983.45	548.667
1985.47	550
1987.5	549.555
1989.52	555.111
1991.55	558.444
1993.57	545.778
1995.59	542.889
1997.62	548
1999.64	547.556
2001.66	549.556
2003.68	545.556
2005.7	558.445
2007.72	560.889
2009.74	555.333
2011.76	550.667
2013.77	559.333
2015.79	555.778
2017.81	545.778
2019.82	559.555
2021.84	552.889
2023.85	551.556
2025.87	561.556
2027.88	557.111
2029.9	552.444
2031.91	556
2033.92	556.444
2035.93	551.778
2037.94	559.333
2039.95	550.222
2041.96	559.111
2043.97	560.889
2045.98	551.333
2047.98	560.222
2049.99	567.556
2052	570
2054	563.778
2056.01	561.556
2058.01	569.778
2060.02	568.667
2062.02	573.778
2064.02	572.667
2066.03	578.667
2068.03	566.889
2070.03	571.333
2072.03	566.889
2074.03	583.778
2076.03	568.667
2078.03	562.222
2080.02	568.667
2082.02	567.778
2084.02	573.111
2086.01	581.333
2088.01	567.778
2090	569.111
2092	566.444
2093.99	576.222
2095.99	563.556
2097.98	571.111
2099.97	563.111
2101.96	570.444
2103.95	573.778
2105.94	558.667
2107.93	578
2109.92	579.556
2111.91	572
2113.9	571.556
2115.88	572.222
2117.87	572
2119.86	558.667
2121.84	563.778
2123.83	571.111
2125.81	564
2127.8	572.889
2129.78	564.667
2131.76	556
2133.74	554.667
2135.73	580
2137.71	564.667
2139.69	552.222
2141.67	564
2143.65	562.889
2145.62	566.889
2147.6	551.333
2149.58	560.667
2151.56	556.444
2153.53	567.333
2155.51	575.778
2157.48	563.111
2159.46	568.667
2161.43	568.889
2163.4	559.333
2165.38	576.667
2167.35	580.889
2169.32	570.889
2171.29	570.222
2173.26	565.556
2175.23	578.444
2177.2	565.556
2179.17	572.889
2181.14	577.556
2183.1	562.889
2185.07	571.778
2187.04	579.111
2189	573.556
2190.97	587.333
2192.93	577.778
2194.89	576.444
2196.86	576.444
2198.82	590.889
2200.78	576.667
2202.74	582.667
2204.71	592
2206.67	570.444
2208.63	582
2210.58	584.444
2212.54	580.445
2214.5	580.889
2216.46	576
2218.42	590.667
2220.37	579.333
2222.33	579.111
2224.28	576.667
2226.24	571.778
2228.19	583.556
2230.14	580
2232.1	563.556
2234.05	571.111
2236	572.889
2237.95	571.556
2239.9	576.222
2241.85	567.778
2243.8	579.778
2245.75	573.556
2247.7	574.444
2249.65	573.778
2251.59	577.778
2253.54	572.889
2255.49	570.222
2257.43	568.667
2259.38	562.222
2261.32	556.222
2263.26	568.889
2265.21	571.111
2267.15	574
2269.09	567.111
2271.03	566.444
2272.97	573.111
2274.92	578.444
2276.85	565.556
2278.79	569.556
2280.73	565.556
2282.67	569.111
2284.61	553.111
2286.54	578.667
2288.48	564.889
2290.42	566.667
2292.35	572.889
2294.29	556.667
2296.22	563.111
2298.15	574.444
2300.09	584.667
2302.02	566
2303.95	574.444
2305.88	576.889
2307.81	581.333
2309.74	574.667
2311.67	572.444
2313.6	578
2315.53	571.556
2317.46	579.333
2319.38	574
2321.31	584.444
2323.24	580.889
2325.16	583.556
2327.09	570.667
2329.01	583.111
2330.94	574.889
2332.86	581.778
2334.78	585.778
2336.7	586
2338.62	572.667
2340.55	571.556
2342.47	591.556
2344.39	576.222
2346.3	580.889
2348.22	563.111
2350.14	577.778
2352.06	576.889
2353.98	575.778
2355.89	572.222
2357.81	591.111
2359.72	576.889
2361.64	585.111
2363.55	572
2365.47	574
2367.38	572.444
2369.29	564.667
2371.21	575.111
2373.12	573.111
2375.03	570.222
2376.94	573.333
2378.85	580.222
2380.76	572
2382.67	578
2384.57	567.556
2386.48	576.222
2388.39	573.778
2390.3	583.778
2392.2	580.444
2394.11	568.889
2396.01	576.444
2397.91	573.333
2399.82	573.111
2401.72	570
2403.62	562.444
2405.53	575.111
2407.43	575.556
2409.33	568.889
2411.23	566.444
2413.13	574.222
2415.03	568.667
2416.93	571.778
2418.82	568.222
2420.72	578.222
2422.62	572.889
2424.52	574.667
2426.41	561.111
2428.31	569.111
2430.2	564.222
2432.1	562.667
2433.99	573.111
2435.88	573.556
2437.78	580.667
2439.67	565.778
2441.56	585.556
2443.45	585.111
2445.34	570.667
2447.23	595.111
2449.12	595.333
2451.01	596.889
2452.9	601.111
2454.79	584.444
2456.67	586.889
2458.56	592.222
2460.44	594
2462.33	580.667
2464.21	597.111
2466.1	602.667
2467.98	582.444
2469.87	578.889
2471.75	595.333
2473.63	590.222
2475.51	590
2477.39	578.889
2479.28	577.333
2481.15	583.111
2483.03	578.889
2484.91	583.333
2486.79	579.556
2488.67	582
2490.55	581.555
2492.42	574.667
2494.3	585.556
2496.18	597.556
2498.05	573.111
2499.93	578
2501.8	586
2503.67	583.111
2505.55	584.444
2507.42	571.333
2509.29	571.556
2511.16	575.778
2513.03	578.889
2514.9	577.556
2516.77	579.333
2518.64	578.222
2520.51	579.556
2522.38	574.889
2524.25	568.444
2526.11	580.667
2527.98	570.444
2529.84	578.889
2531.71	575.333
2533.58	578.444
2535.44	575.556
2537.3	567.333
2539.17	578
2541.03	571.778
2542.89	584.889
2544.75	570.667
2546.61	581.111
2548.48	565.333
2550.34	573.333
2552.2	580.444
2554.05	580.889
2555.91	577.333
2557.77	576
2559.63	573.333
2561.48	570
2563.34	587.111
2565.2	581.111
2567.05	580.889
2568.91	591.555
2570.76	578.667
2572.61	581.778
2574.47	580.222
2576.32	588.889
2578.17	593.111
2580.02	583.778
2581.87	586.444
2583.72	586.222
2585.57	590
2587.42	582.889
2589.27	589.556
2591.12	582
2592.97	589.111
2594.82	596.889
2596.66	603.778
2598.51	588.222
2600.35	604.222
2602.2	606.667
2604.04	612.444
2605.89	608.667
2607.73	620.889
2609.57	623.556
2611.42	627.111
2613.26	642
2615.1	628.444
2616.94	647.778
2618.78	648.889
2620.62	652.667
2622.46	657.111
2624.3	666
2626.14	662.889
2627.98	669.778
2629.81	680.444
2631.65	685.556
2633.49	683.778
2635.32	682.889
2637.16	686.222
2638.99	691.111
2640.82	687.556
2642.66	681.333
2644.49	680.667
2646.32	684.444
2648.16	686.222
2649.99	696.889
2651.82	690.444
2653.65	698.444
2655.48	703.111
2657.31	705.333
2659.14	703.556
2660.96	714.889
2662.79	716.889
2664.62	722
2666.45	734.889
2668.27	739.778
2670.1	777.778
2671.92	784.222
2673.75	808.667
2675.57	835.555
2677.39	866
2679.22	889.111
2681.04	892.889
2682.86	900.444
2684.68	892.889
2686.5	871.333
2688.33	864
2690.15	841.111
2691.96	835.111
2693.78	802
2695.6	778.889
2697.42	754
2699.24	747.778
2701.05	743.333
2702.87	712.222
2704.69	695.778
2706.5	693.556
2708.31	678
2710.13	672
2711.94	654.444
2713.76	651.111
2715.57	645.333
2717.38	636.444
2719.19	630.667
2721	626.222
2722.81	609.111
2724.62	604.667
2726.43	599.778
2728.24	593.556
2730.05	594
2731.86	578.667
2733.67	578.667
2735.47	571.778
2737.28	577.778
2739.09	571.111
2740.89	562.889
2742.7	567.556
2744.5	562.889
2746.31	556
2748.11	557.556
2749.91	560
2751.71	554.667
2753.52	560.444
2755.32	549.778
2757.12	552.667
2758.92	565.556
2760.72	542
2762.52	556.222
2764.32	546
2766.11	550.444
2767.91	552.444
2769.71	560.444
2771.51	551.556
2773.3	552.444
2775.1	562
2776.89	549.556
2778.69	546.889
2780.48	558.222
2782.28	558.222
2784.07	548
2785.86	545.778
2787.65	547.556
2789.45	547.556
2791.24	539.333
2793.03	552.889
2794.82	544
2796.61	538.444
2798.4	541.111
2800.19	542
2801.97	536.444
2803.76	538.444
2805.55	550.222
2807.34	544.667
2809.12	547.333
2810.91	544.889
2812.69	545.333
2814.48	540.444
2816.26	536
2818.04	551.556
2819.83	546.222
2821.61	539.333
2823.39	542.444
2825.17	537.111
2826.95	546.889
2828.73	535.111
2830.51	533.778
2832.29	524.889
2834.07	545.556
2835.85	535.111
2837.63	539.556
2839.41	544.889
2841.18	530.222
2842.96	540.222
2844.74	526.889
2846.51	524.889
2848.29	537.333
2850.06	535.111
2851.84	540.889
2853.61	529.556
2855.38	527.333
2857.15	532.222
2858.93	534.889
2860.7	532
2862.47	536
2864.24	521.556
2866.01	524.444
2867.78	521.778
2869.55	539.111
2871.32	526.889
2873.08	536.222
2874.85	527.333
2876.62	534.444
2878.39	537.556
2880.15	529.556
2881.92	523.111
2883.68	524.889
2885.45	524.667
2887.21	531.111
2888.97	531.778
2890.74	528.444
2892.5	530
2894.26	514
2896.02	528
2897.78	527.556
2899.55	530
2901.31	525.333
2903.07	533.555
2904.82	535.111
2906.58	529.111
2908.34	538.222
2910.1	524.889
2911.86	529.556
2913.61	520
2915.37	532.444
2917.12	532.222
2918.88	523.111
2920.63	524.222
2922.39	519.111
2924.14	528.889
2925.9	528.444
2927.65	532.889
2929.4	520.889
2931.15	528
2932.9	522.667
2934.65	521.778
2936.4	517.556
2938.15	521.111
2939.9	515.333
2941.65	517.778
2943.4	511.333
2945.15	513.778
2946.9	510.222
2948.64	520.222
2950.39	530
2952.13	518
2953.88	513.778
2955.62	510
2957.37	519.111
2959.11	514.889
2960.86	520.889
2962.6	509.778
2964.34	524.222
2966.08	506.222
2967.82	505.333
2969.56	511.556
2971.31	506.444
2973.04	504.444
2974.78	510
2976.52	506.889
2978.26	516.444
2980	500.222
2981.74	512.222
2983.48	503.333
2985.21	504
2986.95	505.111
2988.68	511.778
2990.42	508.444
2992.15	504.444
2993.89	504
2995.62	490.444
2997.35	496.444
2999.09	498.444